<?xml version="1.0"?>
<robot name="my_robot">

    <material name="green">
        <color rgba="0 0.5 0 1" />
    </material>

    <material name="grey">
        <color rgba="0.5 0.5 0.5 1" />
    </material>

    <link name="base_footprint_link">
    </link>

    <link name="base_link">
        <visual>
            <geometry>
                <box size="0.6 0.4 0.2" />
            </geometry>
            <origin xyz="0 0 0.1" rpy="0 0 0"/>
            <material name="green" />
        </visual>
    </link>

    <link name="right_rear_wheel_link">
        <visual>
            <geometry>
                <cylinder radius = "0.1" length = "0.05" />
            </geometry>
            <origin xyz="0 0 0" rpy="1.57 0 0"/>
            <material name="grey" />
        </visual>
    </link>

    <link name="left_rear_wheel_link">
        <visual>
            <geometry>
                <cylinder radius = "0.1" length = "0.05" />
            </geometry>
            <origin xyz="0 0 0" rpy="1.57 0 0"/>
            <material name="grey" />
        </visual>
    </link>

    <link name="front_castor_wheel_link">
        <visual>
            <geometry>
                <sphere radius = "0.05" />
            </geometry>
            <origin xyz="0 0 0" rpy="1.57 0 0"/>
            <material name="grey" />
        </visual>
    </link>

    <joint name = "base_right_rear_wheel_joint" type="continuous">
        <parent link = "base_link"/>
        <child link = "right_rear_wheel_link"/>
        <origin xyz = "-0.15 0.225 0" rpy = "0 0 0"/>
        <axis xyz = "0 1 0" />
    </joint>

    <joint name = "base_left_rear_wheel_joint" type="continuous">
        <parent link = "base_link"/>
        <child link = "left_rear_wheel_link"/>
        <origin xyz = "-0.15 -0.225 0" rpy = "0 0 0"/>
        <axis xyz = "0 1 0" />
    </joint>

    <joint name = "base_front_castor_wheel_link" type="continuous">
        <parent link = "base_link"/>
        <child link = "front_castor_wheel_link"/>
        <origin xyz = "0.15 0 -0.05" rpy = "0 0 0"/>
        <axis xyz = "0 1 0" />
    </joint>

    <joint name = "base_base_footprint_link" type="fixed">
        <parent link = "base_footprint_link"/>
        <child link = "base_link"/>
        <origin xyz = "0 0 0.1" rpy = "0 0 0"/>
    </joint>

</robot>
